<?xml version="1.0"?>

<robot name="rover" xmlns:xacro="http://www.ros.org/wiki/xacro">
<material name="blue">
    <color rgba="0 0 0.8 1"/>
  </material>
  <material name="black">
    <color rgba="0 0 0 1"/>
  </material>
  <material name="white">
    <color rgba="1 1 1 1"/>
  </material>



<!--
<param name="pi" value="3.14159" />
  <link name="base_footprint">
      <inertial>
          <mass value="0.0001" />
          <origin xyz="0 0 0" />
      <inertia ixx="0.0001" ixy="0.0" ixz="0.0"
                         iyy="0.0001" iyz="0.0" 
                         izz="0.0001" />
      </inertial>

      <visual>
          <origin xyz="0 0 0" rpy="0 0 0" />
          <geometry>
             <box size="0.001 0.001 0.001" />
          </geometry>
      </visual>

      <collision>
          <origin xyz="0 0 0.0" rpy="0 0 0" />
          <geometry>
            <box size="0.001 0.001 0.001" />
         </geometry>
     </collision>
  </link>


  <joint name="base_footprint_joint" type="fixed">
     <origin xyz="0 0 0.03125" rpy="0 0 0" />
     <parent link="base_footprint"/>
     <child link="base_link" />
  </joint>
-->
  <link name="base_footprint">
      <inertial>
          <mass value="0.0001" />
          <origin xyz="0 0 0" rpy="0 0 3.14159"/>
      <inertia ixx="0.0001" ixy="0.0" ixz="0.0"
                         iyy="0.0001" iyz="0.0" 
                         izz="0.0001" />
      </inertial>

      <visual>
          <origin xyz="0 0 0" rpy="0 0 0" />
          <geometry>
             <box size="0.001 0.001 0.001" />
          </geometry>
      </visual>

      <collision>
          <origin xyz="0 0 0.0" rpy="0 0 0" />
          <geometry>
            <box size="0.001 0.001 0.001" />
         </geometry>
     </collision>
  </link>

  <joint name="base_footprint_joint" type="fixed">
     <origin xyz="0 0 0.03125" rpy="0 0 0" />
     <parent link="base_footprint"/>
     <child link="base_link" />
  </joint>

  <link name="base_link">
    <visual>
      <origin rpy="0 0 0" xyz="0 0 0"/>
      <geometry>
        <box size="0.205 0.14 0.06"/>
      </geometry>
    </visual>
    <collision>
      <origin rpy="0 0 0" xyz="0 0 0"/>
      <geometry>
        <box size="0.205 0.14 0.06"/>
      </geometry>
    </collision>
    <inertial>
            <mass value="0.0001"/>
      <inertia ixx="0.4" ixy="0.0" ixz="0.0" iyy="0.4" iyz="0.0" izz="0.2"/>
    </inertial>
  </link>

  <joint name="base_mid_joint" type="fixed">
    <parent link="base_link"/>
    <child link="mid_link"/>
    <origin rpy="0 0 0" xyz="0 0 0.06"/>
  </joint>
  <link name="mid_link">
    <visual>
      <origin rpy="0 0 0" xyz="0 0 0"/>
      <geometry>
        <box size="0.18 0.135 0.06"/>
      </geometry>
      <material name="black"/>
      <origin rpy="0 0 0" xyz="0 0 0"/>
    </visual>
    <collision>
      <geometry>
        <box size="0.18 0.135 0.06"/>
      </geometry>
    </collision>
    <inertial>
            <mass value="0.0001"/>
      <inertia ixx="0.4" ixy="0.0" ixz="0.0" iyy="0.4" iyz="0.0" izz="0.2"/>
    </inertial>
  </link>

  <joint name="mid_platform_joint" type="fixed">
    <parent link="mid_link"/>
    <child link="platform_link"/>
    <origin rpy="0 0 0" xyz="0 0 0.0325"/>
  </joint>
  <link name="platform_link">
    <visual>
      <origin rpy="0 0 0" xyz="0 0 0"/>
      <geometry>
        <box size="0.22 0.27 0.005"/>
      </geometry>
      <material name="black"/>
    </visual>
    <collision>
      <geometry>
        <box size="0.22 0.27 0.005"/>
      </geometry>
    </collision>
    <inertial>
            <mass value="0.0001"/>
      <inertia ixx="0.4" ixy="0.0" ixz="0.0" iyy="0.4" iyz="0.0" izz="0.2"/>
    </inertial>
  </link>

  <joint name="platform_top_joint" type="fixed">
    <parent link="platform_link"/>
    <child link="top_link"/>
    <origin rpy="0 0 0" xyz="-0.02 0 0.0325"/>
  </joint>
  <link name="top_link">
    <visual>
      <origin rpy="0 0 0" xyz="0 0 0"/>
      <geometry>
        <box size="0.16 0.205 0.055"/>
      </geometry>
      <material name="black"/>
    </visual>
    <collision>
      <geometry>
        <box size="0.16 0.205 0.055"/>
      </geometry>
    </collision>
    <inertial>
      <mass value="0.0001"/>
      <inertia ixx="0.4" ixy="0.0" ixz="0.0" iyy="0.4" iyz="0.0" izz="0.2"/>
    </inertial>
  </link>

<!-- sensors -->
  <joint name="platform_camera_joint" type="fixed">
    <parent link="platform_link"/>
    <child link="camera_link"/>
    <origin rpy="0 0 0" xyz="0.075 0 0.025"/>
  </joint>
  <link name="camera_link">
    <visual>
      <origin rpy="0 0 0" xyz="0 0 0"/>
      <geometry>
        <box size="0.03 0.04 0.045"/>
      </geometry>
      <material name="black"/>
      <origin rpy="0 0 0" xyz="0 0 0"/>
    </visual>
    <collision>
      <geometry>
        <box size="0.03 0.04 0.045"/>
      </geometry>
    </collision>
    <inertial>
      <mass value="0.0001"/>
      <inertia ixx="0.4" ixy="0.0" ixz="0.0" iyy="0.4" iyz="0.0" izz="0.2"/>
    </inertial>
  </link>

  <joint name="top_rplidar_joint" type="fixed">
    <parent link="top_link"/>
    <child link="rplidar_link"/>
    <origin rpy="0 0 3.14159" xyz="0 0 0.0525"/>
  </joint>
  <link name="rplidar_link">
    <visual>
      <origin rpy="0 0 0" xyz="0 0 0"/>
      <geometry>
        <cylinder length="0.05" radius="0.06"/>
      </geometry>
      <material name="black"/>
      <origin rpy="0 0 0" xyz="0 0 0"/>
    </visual>
    <collision>
      <geometry>
        <cylinder length="0.05" radius="0.06"/>
      </geometry>
    </collision>
    <inertial>
      <mass value="0.0001"/>
      <inertia ixx="0.4" ixy="0.0" ixz="0.0" iyy="0.4" iyz="0.0" izz="0.2"/>
    </inertial>
  </link>

  <joint name="base_fcu_joint" type="fixed">
    <parent link="base_link"/>
    <child link="fcu"/>
    <origin rpy="0 0 0" xyz="0.06 0 0.035"/>
  </joint>
  <link name="fcu">
    <visual>
      <origin rpy="0 0 0" xyz="0 0 0"/>
      <geometry>
        <box size="0.09 0.05 0.015"/>
      </geometry>
      <material name="black"/>
      <origin rpy="0 0 0" xyz="0 0 0"/>
    </visual>
    <collision>
      <geometry>
        <box size="0.09 0.05 0.015"/>
      </geometry>
    </collision>
    <inertial>
      <mass value="0.0001"/>
      <inertia ixx="0.4" ixy="0.0" ixz="0.0" iyy="0.4" iyz="0.0" izz="0.2"/>
    </inertial>
  </link>

<!-- wheels 
  <xacro:macro name="wheel" params="prefix suffix reflectx reflecty">

    <link name="${prefix}_${suffix}_wheel">
      <visual>
        <origin xyz="0 0 0" rpy="1.570796 0 0" />
        <geometry>
          <cylinder length="0.07" radius="0.0625"/>
        </geometry>
        <origin xyz="0 0 0" rpy="0 0 0" />
        <material name="black"/>
      </visual>
      <collision>
        <origin xyz="0 0 0" rpy="1.570796 0 0" />
        <geometry>
          <cylinder length="0.07" radius="0.0625"/>
        </geometry>
        <origin xyz="0 0 0" rpy="0 0 0" />
      </collision>
      <inertial>
        <mass value="0.0001"/>
        <inertia ixx="2e-08" ixy="0" ixz="0" iyy="3e-08" iyz="0" izz="2e-08"/>
      </inertial>
    </link>
    <joint name="${prefix}_${suffix}_wheel_joint" type="continuous">

      <axis xyz="0 1 0" rpy="0 0 0" />
      <parent link="base_link"/>
      <child link="${prefix}_${suffix}_wheel"/>
      <origin xyz="${reflectx*0.1025} ${reflecty*0.115} 0" rpy="0 0 0"/>
    </joint>
    <transmission name="${prefix}_${suffix}_wheel_trans" type="SimpleTransmission">
      <type>transmission_interface/SimpleTransmission</type>
      <actuator name="${prefix}_${suffix}_wheel_motor">
        <mechanicalReduction>1</mechanicalReduction>
      </actuator>
      <joint name="${prefix}_${suffix}_wheel_joint">
        <hardwareInterface>hardware_interface/VelocityJointInterface</hardwareInterface>

      <axis xyz="0 1 0" rpy="0 0 0" />
      <parent link="base_link"/>
      <child link="${prefix}_${suffix}_wheel"/>
      <origin xyz="${reflectx*0.1025} ${reflecty*0.115} 0" rpy="0 0 0"/>

      </joint>
    </transmission>

    <gazebo reference="${prefix}_${suffix}_wheel">
      <mu1 value="200.0"/>
      <mu2 value="100.0"/>
      <kp value="10000000.0" />
      <kd value="1.0" />
    </gazebo>

  </xacro:macro>
  <xacro:wheel prefix="right" suffix="front" reflectx="1" reflecty="1"/>
  <xacro:wheel prefix="left" suffix="front" reflectx="-1" reflecty="1"/>
  <xacro:wheel prefix="right" suffix="back" reflectx="1" reflecty="-1"/>
  <xacro:wheel prefix="left" suffix="back" reflectx="-1" reflecty="-1"/>

wheels -->

    <link name="right_front_wheel">
      <visual>
        <origin xyz="0 0 0" rpy="1.570796 0 0" />
        <geometry>
          <cylinder length="0.07" radius="0.0625"/>
        </geometry>
        <origin xyz="0 0 0" rpy="0 0 0" />
        <material name="black"/>
      </visual>
      <collision>
        <origin xyz="0 0 0" rpy="1.570796 0 0" />
        <geometry>
          <cylinder length="0.07" radius="0.0625"/>
        </geometry>
        <origin xyz="0 0 0" rpy="0 0 0" />
      </collision>
      <inertial>
        <mass value="0.0001"/>
        <inertia ixx="2e-08" ixy="0" ixz="0" iyy="3e-08" iyz="0" izz="2e-08"/>
      </inertial>
    </link>
    <joint name="right_front_wheel_joint" type="continuous">
      <axis xyz="0 1 0" rpy="0 0 0" />
      <parent link="base_link"/>
      <child link="right_front_wheel"/>
      <origin xyz="0.1025 0.115 0" rpy="0 0 0"/>
    </joint>

    <link name="left_front_wheel">
      <visual>
        <origin xyz="0 0 0" rpy="1.570796 0 0" />
        <geometry>
          <cylinder length="0.07" radius="0.0625"/>
        </geometry>
        <origin xyz="0 0 0" rpy="0 0 0" />
        <material name="black"/>
      </visual>
      <collision>
        <origin xyz="0 0 0" rpy="1.570796 0 0" />
        <geometry>
          <cylinder length="0.07" radius="0.0625"/>
        </geometry>
        <origin xyz="0 0 0" rpy="0 0 0" />
      </collision>
      <inertial>
        <mass value="0.0001"/>
        <inertia ixx="2e-08" ixy="0" ixz="0" iyy="3e-08" iyz="0" izz="2e-08"/>
      </inertial>
    </link>
    <joint name="left_front_wheel_joint" type="continuous">
      <axis xyz="0 1 0" rpy="0 0 0" />
      <parent link="base_link"/>
      <child link="left_front_wheel"/>
      <origin xyz="-0.1025 0.115 0" rpy="0 0 0"/>
    </joint>

    <link name="right_back_wheel">
      <visual>
        <origin xyz="0 0 0" rpy="1.570796 0 0" />
        <geometry>
          <cylinder length="0.07" radius="0.0625"/>
        </geometry>
        <origin xyz="0 0 0" rpy="0 0 0" />
        <material name="black"/>
      </visual>
      <collision>
        <origin xyz="0 0 0" rpy="1.570796 0 0" />
        <geometry>
          <cylinder length="0.07" radius="0.0625"/>
        </geometry>
        <origin xyz="0 0 0" rpy="0 0 0" />
      </collision>
      <inertial>
        <mass value="0.0001"/>
        <inertia ixx="2e-08" ixy="0" ixz="0" iyy="3e-08" iyz="0" izz="2e-08"/>
      </inertial>
    </link>
    <joint name="right_back_wheel_joint" type="continuous">

      <axis xyz="0 1 0" rpy="0 0 0" />
      <parent link="base_link"/>
      <child link="right_back_wheel"/>
      <origin xyz="0.1025 -0.115 0" rpy="0 0 0"/>
    </joint>

    <link name="left_back_wheel">
      <visual>
        <origin xyz="0 0 0" rpy="1.570796 0 0" />
        <geometry>
          <cylinder length="0.07" radius="0.0625"/>
        </geometry>
        <origin xyz="0 0 0" rpy="0 0 0" />
        <material name="black"/>
      </visual>
      <collision>
        <origin xyz="0 0 0" rpy="1.570796 0 0" />
        <geometry>
          <cylinder length="0.07" radius="0.0625"/>
        </geometry>
        <origin xyz="0 0 0" rpy="0 0 0" />
      </collision>
      <inertial>
        <mass value="0.0001"/>
        <inertia ixx="2e-08" ixy="0" ixz="0" iyy="3e-08" iyz="0" izz="2e-08"/>
      </inertial>
    </link>
    <joint name="left_back_wheel_joint" type="continuous">
      <axis xyz="0 1 0" rpy="0 0 0" />
      <parent link="base_link"/>
      <child link="left_back_wheel"/>
      <origin xyz="-0.1025 -0.115 0" rpy="0 0 0"/>
    </joint>
</robot>
